2025-10-18T20:34:49.198538+00:00 app[worker.1]: INFO:httpx:HTTP Request: GET https://dqomvlyrrezythpqncsf.supabase.co/rest/v1/friends?select=%2A&user_id=eq.8058c701-8142-43ae-b647-323a68e25a4c "HTTP/2 200 OK"
2025-10-18T20:34:49.243763+00:00 app[worker.1]: INFO:google_genai.models:AFC is enabled with max remote calls: 10.
2025-10-18T20:35:04.601619+00:00 app[worker.1]: INFO:httpx:HTTP Request: POST https://generativelanguage.googleapis.com/v1beta/models/gemini-2.5-flash:generateContent "HTTP/1.1 200 OK"
2025-10-18T20:35:05.463092+00:00 app[worker.1]: INFO:httpx:HTTP Request: GET https://dqomvlyrrezythpqncsf.supabase.co/rest/v1/friends?select=friend_user_id%2Cnickname&user_id=eq.8058c701-8142-43ae-b647-323a68e25a4c&nickname=ilike.Shri&limit=1 "HTTP/2 200 OK"
2025-10-18T20:35:05.755308+00:00 app[worker.1]: INFO:httpx:HTTP Request: GET https://dqomvlyrrezythpqncsf.supabase.co/rest/v1/profiles?select=%2A&telegram_id=eq.599013963&limit=1 "HTTP/2 200 OK"
2025-10-18T20:35:05.756112+00:00 app[worker.1]: ERROR:__main__:Error inserting transaction: 'SyncQueryRequestBuilder' object has no attribute 'select'
2025-10-18T20:35:05.756825+00:00 app[worker.1]: ERROR:__main__:Error handling input: DB error inserting transaction
2025-10-18T20:35:05.756826+00:00 app[worker.1]: Traceback (most recent call last):
2025-10-18T20:35:05.756826+00:00 app[worker.1]:   File "/app/backend/bot.py", line 136, in insert_transaction_and_children
2025-10-18T20:35:05.756827+00:00 app[worker.1]:     tx_res = supabase.table("transactions").insert(txn_payload).select("id").execute()
2025-10-18T20:35:05.756828+00:00 app[worker.1]:              ^^^^^^^^^^^^^^^^^^^^^^^^^^^^^^^^^^^^^^^^^^^^^^^^^^^^^^^^^
2025-10-18T20:35:05.756828+00:00 app[worker.1]: AttributeError: 'SyncQueryRequestBuilder' object has no attribute 'select'
2025-10-18T20:35:05.756828+00:00 app[worker.1]: 
2025-10-18T20:35:05.756828+00:00 app[worker.1]: During handling of the above exception, another exception occurred:
2025-10-18T20:35:05.756829+00:00 app[worker.1]: 
2025-10-18T20:35:05.756829+00:00 app[worker.1]: Traceback (most recent call last):
2025-10-18T20:35:05.756829+00:00 app[worker.1]:   File "/app/backend/bot.py", line 255, in handle_input
2025-10-18T20:35:05.756829+00:00 app[worker.1]:     insert_transaction_and_children(
2025-10-18T20:35:05.756830+00:00 app[worker.1]:   File "/app/backend/bot.py", line 141, in insert_transaction_and_children
2025-10-18T20:35:05.756830+00:00 app[worker.1]:     raise RuntimeError("DB error inserting transaction")
2025-10-18T20:35:05.756830+00:00 app[worker.1]: RuntimeError: DB error inserting transaction
2025-10-18T20:35:06.312403+00:00 app[worker.1]: INFO:httpx:HTTP Request: POST https://api.telegram.org/bot7651391698:AAFed15lajiauDRvyAtS4nt68koYr-4EDEI/sendMessage "HTTP/1.1 200 OK"
2025-10-18T20:35:16.019488+00:00 app[worker.1]: INFO:httpx:HTTP Request: POST https://api.telegram.org/bot7651391698:AAFed15lajiauDRvyAtS4nt68koYr-4EDEI/getUpdates "HTTP/1.1 200 OK"